Workbook
Name SS: 'PERIOD 5'!#REF!

Sheet normuren
A1: Course development | B1: Hours
A2: New | B2: 150
A3: Adapted | B3: 100
A4: Existing | B4: 50
A5: Total
A7: Course coordination | B7: Hours
A8: 1-2 tutorial groups | B8: 15
A9: 3-5 tutorial groups | B9: 30
A10: 6-8 tutorial groups | B10: 45
A11: 9 and more tutorial groups | B11: 60
A14: Curriculum development | B14: Hours
A15: Curriculum committee chairman | B15: 150 | C15: per academic year
A16: Curriculum committee member | B16: 80 | C16: per academic year
A17: Board of studies chairman | B17: 100 | C17: per academic year
A18: Board of studies member | B18: 30 | C18: per academic year
A19: Vice Dean | B19: 300 | C19: per academic year
A20: Course development | B20: 50-150 | C20: depending on workload
A22: Teaching
A23: Course coordination | B23: 15-60 | C23: depending on group size
A24: Tutors | B24: 1.5 | C24: per tutorial hour
A25: Tutors (1st Year JTF) | B25: 1.9 | C25: per tutorial hour
A26: Lectures | B26: 3 | C26: per lecturing hour
A27: Tutors skills training | B27: 20 | C27: per group
A28: Tutors projects | B28: 10 | C28: per group
A29: Assessment (1,5 hours per student per course) | B29: 1.5 | C29: per student per course
A30: Assessment assignments writing and projects | B30: 1.5 | C30: per student per course
A39: Fixed roles
A40: Admissions Interview | B40: 1 | C40: per student per interview
A41: Examination board chair | B41: 800 | C41: per academic year
A42: Examination board member | B42: 25 | C42: per academic year
A43: Board of Survey chair | B43: 50 | C43: per academic year
A44: Board of Survey member | B44: 25 | C44: per academic year
A45: Skills coordination | B45: 100 | C45: per academic year
A46: Science Coordination | B46: 130 | C46: per academic year
A47: Board of Admissions member | B47: 20 | C47: per academic year
A48: AA coordination/committee | B48: 700 | C48: per academic year
A49: Capstone supervision | B49: 12 | C49: per student per capstone
A50: Capstone 2nd grader | B50: 4 | C50: per student per capstone
A51: Curriculum evaluation | B51: 120 | C51: per academic year
... A57: Universalis board member | B57: 1500 | C57: per academic year

Sheet PERIOD 1
A1: PERIOD 1 | K1: Hours | AU1: Junior Lecturers (D4) & OBP | AV1: Junior Lecturers (D4) & OBP
A2: CODE | B2: COURSE TITLE | C2: Faculty | D2: COORDINATOR | E2: NR | F2: TG | G2: TG | H2: ST/TG | I2: Lect | J2: lect | K2: CO | L2: per TG regular staff | M2: Per TG 1st Year JTF | N2: Per ST | O2: FAC | P2: Lbe | Q2: LB | R2: Sca | S2: TD | T2: WvD | U2: CE | V2: AF | W2: WG | X2: TG | Y2: RH | Z2: CH | AA2: KH | AB2: MH | AC2: MK | AD2: MK | AE2: VL | AF2: EM | AG2: DM | AH2: JM | AI2: UM | AJ2: AO | AK2: JvP | AL2: CR | AM2: IR | AN2: JS | AO2: BS | AP2: MS | AQ2: PV | AR2: DV | AS2: JW | AT2: AW | AU2: CYPL | AV2: JB/OBP | AW2: SB/D4 | AX2: CC/OBP | AY2: XT/D4 | AZ2: RvE/D4 | BA2: ZE/OBP | BB2: CG/D4 | BC2: JH/D4 | BD2: WH/D4 | BE2: JvL/D4 | BF2: IM/D4 | BG2: MM/D4 | BH2: APT/D4 | BI2: WS/D4 | BJ2: KK/D4 | BK2: JvZ/D4 | BL2: WOS/OBP | BM2: Total | BN2: TG problem
A4: CAP3000 | B4: Capstone | C4: UCM | D4: J. Moes/ E. Maegherman | E4: 57 | G4: 5 | X4: X | Y4: ? | AE4: 1 | AF4: 1 | AH4: 1 | AL4: 1 | AN4: X | AQ4: 1 | AR4: NO | AS4: X | AT4: NO | AU4: X
A5: COR1003 | B5: Contemporary World History | C5: UCM | D5: M. Stout | E5: 240 | F5: =E5/13 -> 18.461538 | G5: =ROUNDUP(F5,0) -> 19 | H5: =IF(G5=0,0,E5/G5) -> 12.631579 | J5: =I5*2*normuren!$B$26 -> 0 | K5: =IF(G5<3,normuren!$B$8,IF(AND(G5<6,G5>2),normuren!$B$9,IF(AND(G5<9,G5>5),normuren!$B$10,normuren!$B$11))) -> 60 | L5: =normuren!$B$24*2*12 -> 36 | M5: =normuren!$B$25*2*12 -> 45.6 | N5: =normuren!$B$29 -> 1.5 | O5: X | V5: NO | AK5: 2 | AP5: 2 | AW5: 3 | AY5: 3 | BA5: 3 | BE5: X | BG5: NO | BI5: 3 | BJ5: 3 | BM5: =SUM(O5:BL5) -> 19 | BN5: =G5-BM5 -> 0 | BO5: =IF(BN5>0,"Problem","Oke") -> Oke | BP5: no FP in BP 1; zeta/ceren
A6: COR1006 | B6: Science, Reason and Human Progress | C6: UCM | D6: M. Heins | E6: 157 | F6: =$E6/13 -> 12.076923 | G6: =ROUNDUP(F6,0) -> 13 | H6: =IF(G6=0,0,E6/G6) -> 12.076923 | J6: =I6*2*normuren!$B$26 -> 0 | K6: =IF(G6<3,normuren!$B$8,IF(AND(G6<6,G6>2),normuren!$B$9,IF(AND(G6<9,G6>5),normuren!$B$10,normuren!$B$11))) -> 60 | L6: =normuren!$B$27 -> 20 | M6: 20 | N6: =normuren!$B$29 -> 1.5 | O6: X | X6: X | AB6: 3 | AK6: X | AV6: 3 | AX6: 2 | AZ6: 2 | BB6: X | BC6: 3 | BE6: NO | BG6: X | BH6: X | BM6: =SUM(O6:BL6) -> 13 | BN6: =G6-BM6 -> 0 | BO6: =IF(BN6>0,"Problem","Oke") -> Oke | BP6: Rikus van Eeden 2 TG's Global Studies
A7: HUM1011 | B7: Introduction to Art; Representations, Performances and Interactions | C7: UCM | D7: C. Rausch -> I. Romgens | E7: 39 | F7: =E7/12 -> 3.25 | G7: 3 | H7: =IF(G7=0,0,E7/G7) -> 13 | J7: =I7*2*normuren!$B$26 -> 0 | K7: =IF(G7<3,normuren!$B$8,IF(AND(G7<6,G7>2),normuren!$B$9,IF(AND(G7<9,G7>5),normuren!$B$10,normuren!$B$11))) -> 30 | L7: =normuren!$B$24*2*12 -> 36 | M7: =normuren!$B$25*2*12 -> 45.6 | N7: =normuren!$B$29 -> 1.5 | AM7: 1 | BE7: 2 | BM7: =SUM(O7:BL7) -> 3 | BN7: =G7-BM7 -> 0 | BO7: =IF(BN7>0,"Problem","Oke") -> Oke
A8: HUM2058 | B8: History of Contemporary Spirituality | C8: UCM | D8: D. Vliegenthart | E8: 16 | F8: =E8/8 -> 2 | G8: =ROUNDUP(F8,0) -> 2 | H8: =IF(G8=0,0,E8/G8) -> 8 | J8: =I8*2*normuren!$B$26 -> 0 | K8: =IF(G8<3,normuren!$B$8,IF(AND(G8<6,G8>2),normuren!$B$9,IF(AND(G8<9,G8>5),normuren!$B$10,normuren!$B$11))) -> 15 | L8: =normuren!$B$24*2*12 -> 36 | M8: =normuren!$B$25*2*12 -> 45.6 | N8: =normuren!$B$29 -> 1.5 | AR8: 2 | BM8: =SUM(O8:BL8) -> 2 | BN8: =G8-BM8 -> 0 | BO8: =IF(BN8>0,"Problem","Oke") -> Oke
A9: SCI1009 | B9: Introduction to Biology | C9: UCM | D9: B. Schmitz | E9: 37 | F9: =E9/13 -> 2.8461538 | G9: =ROUNDUP(F9,0) -> 3 | H9: =IF(G9=0,0,E9/G9) -> 12.333333 | J9: =I9*2*normuren!$B$26 -> 0 | K9: =IF(G9<3,normuren!$B$8,IF(AND(G9<6,G9>2),normuren!$B$9,IF(AND(G9<9,G9>5),normuren!$B$10,normuren!$B$11))) -> 30 | L9: =normuren!$B$24*2*12 -> 36 | M9: =normuren!$B$25*2*12 -> 45.6 | N9: =normuren!$B$29 -> 1.5 | AO9: 1 | AX9: 2 | BM9: =SUM(O9:BL9) -> 3 | BN9: =G9-BM9 -> 0 | BO9: =IF(BN9>0,"Problem","Oke") -> Oke
A10: SCI2042 | B10: Infectious Diseases and Global Public Health | C10: UCM | D10: C. Lo | E10: 37 | F10: =E10/13 -> 2.8461538 | G10: =ROUNDUP(F10,0) -> 3 | H10: =IF(G10=0,0,E10/G10) -> 12.333333 | J10: =I10*2*normuren!$B$26 -> 0 | K10: =IF(G10<3,normuren!$B$8,IF(AND(G10<6,G10>2),normuren!$B$9,IF(AND(G10<9,G10>5),normuren!$B$10,normuren!$B$11))) -> 30 | L10: =normuren!$B$27 -> 20 | M10: 20 | N10: =normuren!$B$29 -> 1.5 | AO10: X | AU10: 3 | BM10: =SUM(O10:BL10) -> 3 | BN10: =G10-BM10 -> 0 | BO10: =IF(BN10>0,"Problem","Oke") -> Oke
A11: SKI1004 | B11: Research Methods I | C11: UCM | D11: J. Moes - > E. Maegherman | E11: 50 | F11: =E11/12 -> 4.1666667 | G11: 4 | H11: =IF(G11=0,0,E11/G11) -> 12.5 | J11: =I11*2*normuren!$B$26 -> 0 | K11: =IF(G11<3,normuren!$B$8,IF(AND(G11<6,G11>2),normuren!$B$9,IF(AND(G11<9,G11>5),normuren!$B$10,normuren!$B$11))) -> 30 | L11: =normuren!$B$27 -> 20 | M11: 20 | N11: =normuren!$B$29 -> 1.5 | O11: X | AF11: 1 | AH11: 1 | BI11: 2 | BL11: X | BM11: =SUM(O11:BL11) -> 4 | BN11: =G11-BM11 -> 0 | BO11: =IF(BN11>0,"Problem","Oke") -> Oke
A12: SKI1008 | B12: Introduction to Academic Skills I | C12: UCM | D12: A. Wellum / A. Foster | E12: 253 | F12: =E12/12 -> 21.083333 | G12: 23 | H12: =IF(G12=0,0,E12/G12) -> 11 | J12: =I12*2*normuren!$B$26 -> 0 | K12: =IF(G12<3,normuren!$B$8,IF(AND(G12<6,G12>2),normuren!$B$9,IF(AND(G12<9,G12>5),normuren!$B$10,normuren!$B$11))) -> 60 | L12: =normuren!$B$24*2*12 -> 36 | M12: =normuren!$B$25*2*12 -> 45.6 | N12: =normuren!$B$29 -> 1.5 | O12: X | V12: 2 | AD12: 2 | AT12: 2 | AV12: 2 | AX12: X | AY12: 2 | BB12: 2 | BD12: 3 | BE12: 3 | BG12: 3 | BJ12: 2 | BL12: X | BM12: =SUM(O12:BL12) -> 23 | BN12: =G12-BM12 -> 0 | BO12: =IF(BN12>0,"Problem","Oke") -> Oke
A13: SKI2007 | B13: Presentation Skills | C13: UCM | D13: D. Vliegenthart | E13: 110 | F13: =E13/8 -> 13.75 | G13: =ROUNDUP(F13,0) -> 14 | H13: =IF(G13=0,0,E13/G13) -> 7.8571429 | J13: =I13*2*normuren!$B$26 -> 0 | K13: =IF(G13<3,normuren!$B$8,IF(AND(G13<6,G13>2),normuren!$B$9,IF(AND(G13<9,G13>5),normuren!$B$10,normuren!$B$11))) -> 60 | L13: =normuren!$B$24*2*12 -> 36 | M13: =normuren!$B$25*2*12 -> 45.6 | N13: =normuren!$B$29 -> 1.5 | X13: 1 | AR13: 1 | AW13: 2 | AZ13: 0 | BA13: 1 | BB13: 3 | BD13: 3 | BE13: X | BH13: 3 | BL13: NO | BM13: =SUM(O13:BL13) -> 14 | BN13: =G13-BM13 -> 0 | BO13: =IF(BN13>0,"Problem","Oke") -> Oke
A14: SKI2049 | B14: Argumentation I | C14: UCM | D14: W. Giernalczyk | E14: 124 | F14: =E14/12 -> 10.333333 | G14: =ROUNDUP(F14,0) -> 11 | H14: =IF(G14=0,0,E14/G14) -> 11.272727 | J14: =I14*2*normuren!$B$26 -> 0 | K14: =IF(G14<3,normuren!$B$8,IF(AND(G14<6,G14>2),normuren!$B$9,IF(AND(G14<9,G14>5),normuren!$B$10,normuren!$B$11))) -> 60 | L14: =normuren!$B$27 -> 20 | M14: 20 | N14: =normuren!$B$29 -> 1.5 | O14: 2 | U14: 3 | W14: 1 | AQ14: 1 | BC14: 2 | BG14: 2 | BI14: X | BM14: =SUM(O14:BL14) -> 11 | BN14: =G14-BM14 -> 0 | BO14: =IF(BN14>0,"Problem","Oke") -> Oke
A15: SKI2085 | B15: Ethnography and Qualitative Interviewing I | C15: UCM | D15: U. Müller | E15: 46 | F15: =E15/12 -> 3.8333333 | G15: =ROUNDUP(F15,0) -> 4 | H15: =IF(G15=0,0,E15/G15) -> 11.5 | J15: =I15*2*normuren!$B$26 -> 0 | K15: =IF(G15<3,normuren!$B$8,IF(AND(G15<6,G15>2),normuren!$B$9,IF(AND(G15<9,G15>5),normuren!$B$10,normuren!$B$11))) -> 30 | L15: =normuren!$B$27 -> 20 | M15: 20 | N15: =normuren!$B$29 -> 1.5 | AA15: X | AE15: X | AH15: X | AI15: 1 | AL15: X | BB15: X | BF15: 2 | BL15: 1 | BM15: =SUM(O15:BL15) -> 4 | BN15: =G15-BM15 -> 0 | BO15: =IF(BN15>0,"Problem","Oke") -> Oke
A16: SSC1029 | B16: Sociological Perspectives | C16: UCM | D16: K. Heidemann | E16: 63 | F16: =E16/12 -> 5.25 | G16: 6 | H16: =IF(G16=0,0,E16/G16) -> 10.5 | J16: =I16*2*normuren!$B$26 -> 0 | K16: =IF(G16<3,normuren!$B$8,IF(AND(G16<6,G16>2),normuren!$B$9,IF(AND(G16<9,G16>5),normuren!$B$10,normuren!$B$11))) -> 45 | L16: =normuren!$B$24*2*12 -> 36 | M16: =normuren!$B$25*2*12 -> 45.6 | N16: =normuren!$B$29 -> 1.5 | O16: 4 | AA16: NO | AE16: 2 | BM16: =SUM(O16:BL16) -> 6 | BN16: =G16-BM16 -> 0 | BO16: =IF(BN16>0,"Problem","Oke") -> Oke
A17: SSC3036 | B17: American Foreign Policy | C17: UCM | D17: R. Haar | E17: 29 | F17: =E17/12 -> 2.4166667 | G17: 3 | H17: =IF(G17=0,0,E17/G17) -> 9.6666667 | J17: =I17*2*normuren!$B$26 -> 0 | K17: =IF(G17<3,normuren!$B$8,IF(AND(G17<6,G17>2),normuren!$B$9,IF(AND(G17<9,G17>5),normuren!$B$10,normuren!$B$11))) -> 30 | L17: =normuren!$B$24*2*12 -> 36 | M17: =normuren!$B$25*2*12 -> 45.6 | N17: =normuren!$B$29 -> 1.5 | U17: 2 | Y17: 1 | BG17: X | BM17: =SUM(O17:BL17) -> 3 | BN17: =G17-BM17 -> 0 | BO17: =IF(BN17>0,"Problem","Oke") -> Oke
A18: UGR3001 | B18: MaRBLe Undergraduate Research | C18: UCM | D18: J. Moes / U. Müller | E18: 18 | F18: =E18/12 -> 1.5 | G18: =ROUNDUP(F18,0) -> 2 | H18: =IF(G18=0,0,E18/G18) -> 9 | J18: =I18*2*normuren!$B$26 -> 0 | K18: =IF(G18<3,normuren!$B$8,IF(AND(G18<6,G18>2),normuren!$B$9,IF(AND(G18<9,G18>5),normuren!$B$10,normuren!$B$11))) -> 15 | L18: =normuren!$B$24*2*12 -> 36 | M18: =normuren!$B$25*2*12 -> 45.6 | N18: =normuren!$B$29 -> 1.5 | AF18: X | AH18: X | BM18: =SUM(O18:BL18) -> 0 | BN18: =G18-BM18 -> 2 | BO18: =IF(BN18>0,"Problem","Oke") -> Problem
A19: UGR3003 | B19: Applied Research & Internship Project | C19: UCM | D19: I. Römgens | E19: 8 | F19: =E19/12 -> 0.66666667 | G19: =ROUNDUP(F19,0) -> 1 | H19: =IF(G19=0,0,E19/G19) -> 8 | J19: =I19*2*normuren!$B$26 -> 0 | K19: =IF(G19<3,normuren!$B$8,IF(AND(G19<6,G19>2),normuren!$B$9,IF(AND(G19<9,G19>5),normuren!$B$10,normuren!$B$11))) -> 15 | L19: =normuren!$B$24*2*12 -> 36 | M19: =normuren!$B$25*2*12 -> 45.6 | N19: =normuren!$B$29 -> 1.5 | T19: X | AH19: X | AL19: X | AM19: X | AU19: X | BM19: =SUM(O19:BL19) -> 0 | BN19: =G19-BM19 -> 1 | BO19: =IF(BN19>0,"Problem","Oke") -> Problem
A20: HUM1007 | B20: Introduction to Philosophy | C20: FASOS | D20: R. Gabriels | E20: 52 | F20: =$E20/12 -> 4.3333333 | G20: 4 | H20: =IF(G20=0,0,E20/G20) -> 13 | J20: =I20*2*normuren!$B$26 -> 0 | K20: =IF(G20<3,normuren!$B$8,IF(AND(G20<6,G20>2),normuren!$B$9,IF(AND(G20<9,G20>5),normuren!$B$10,normuren!$B$11))) -> 30 | L20: =normuren!$B$24*2*12 -> 36 | M20: =normuren!$B$25*2*12 -> 45.6 | N20: =normuren!$B$29 -> 1.5 | BM20: =SUM(O20:BL20) -> 0 | BN20: =G20-BM20 -> 4 | BO20: =IF(BN20>0,"Problem","Oke") -> Problem
A21: HUM1012 | B21: Pop Songs and Poetry: Theory and Analysis | C21: FASOS | D21: J. Weusten | E21: 29 | F21: =E21/12 -> 2.4166667 | G21: =ROUNDUP(F21,0) -> 3 | H21: =IF(G21=0,0,E21/G21) -> 9.6666667 | J21: =I21*2*normuren!$B$26 -> 0 | K21: =IF(G21<3,normuren!$B$8,IF(AND(G21<6,G21>2),normuren!$B$9,IF(AND(G21<9,G21>5),normuren!$B$10,normuren!$B$11))) -> 30 | L21: =normuren!$B$27 -> 20 | M21: 20 | N21: =normuren!$B$29 -> 1.5 | O21: X | BM21: =SUM(O21:BL21) -> 0 | BN21: =G21-BM21 -> 3 | BO21: =IF(BN21>0,"Problem","Oke") -> Problem
A22: HUM2003 | B22: The Making of Crucial Differences: ‘Race’, Sexuality, Gender, and Class in Historical Perspective | C22: FASOS | D22: Lies Wesseling | E22: 64 | F22: =E22/12 -> 5.3333333 | G22: =ROUNDUP(F22,0) -> 6 | H22: =IF(G22=0,0,E22/G22) -> 10.666667 | J22: =I22*2*normuren!$B$26 -> 0 | K22: =IF(G22<3,normuren!$B$8,IF(AND(G22<6,G22>2),normuren!$B$9,IF(AND(G22<9,G22>5),normuren!$B$10,normuren!$B$11))) -> 45 | L22: =normuren!$B$24*2*12 -> 36 | M22: =normuren!$B$25*2*12 -> 45.6 | N22: =normuren!$B$29 -> 1.5 | O22: 4 | BF22: 2 | BH22: 0 | BI22: X | BM22: =SUM(O22:BL22) -> 6 | BN22: =G22-BM22 -> 0 | BO22: =IF(BN22>0,"Problem","Oke") -> Oke
A23: HUM2005 | B23: Enlightenment and Romanticism | C23: FASOS | D23: M. Doorman | E23: 16 | F23: =E23/12 -> 1.3333333 | G23: =ROUNDUP(F23,0) -> 2 | H23: =IF(G23=0,0,E23/G23) -> 8 | J23: =I23*2*normuren!$B$26 -> 0 | K23: =IF(G23<3,normuren!$B$8,IF(AND(G23<6,G23>2),normuren!$B$9,IF(AND(G23<9,G23>5),normuren!$B$10,normuren!$B$11))) -> 15 | L23: =normuren!$B$24*2*12 -> 36 | M23: =normuren!$B$25*2*12 -> 45.6 | N23: =normuren!$B$29 -> 1.5 | BM23: =SUM(O23:BL23) -> 0 | BN23: =G23-BM23 -> 2 | BO23: =IF(BN23>0,"Problem","Oke") -> Problem
A24: HUM2046 | B24: Science and Technology Studies 1: Living in a Technological Culture | C24: FASOS | D24: J. Mesman | E24: 42 | F24: =E24/12 -> 3.5 | G24: 4 | H24: =IF(G24=0,0,E24/G24) -> 10.5 | J24: =I24*2*normuren!$B$26 -> 0 | K24: =IF(G24<3,normuren!$B$8,IF(AND(G24<6,G24>2),normuren!$B$9,IF(AND(G24<9,G24>5),normuren!$B$10,normuren!$B$11))) -> 30 | L24: =normuren!$B$24*2*12 -> 36 | M24: =normuren!$B$25*2*12 -> 45.6 | N24: =normuren!$B$29 -> 1.5 | BM24: =SUM(O24:BL24) -> 0 | BN24: =G24-BM24 -> 4 | BO24: =IF(BN24>0,"Problem","Oke") -> Problem
A25: HUM3036 | B25: Narrative Media | C25: FASOS | D25: R. van de Vall R. Ausmeier | E25: 35 | F25: =E25/12 -> 2.9166667 | G25: =ROUNDUP(F25,0) -> 3 | H25: =IF(G25=0,0,E25/G25) -> 11.666667 | J25: =I25*2*normuren!$B$26 -> 0 | K25: =IF(G25<3,normuren!$B$8,IF(AND(G25<6,G25>2),normuren!$B$9,IF(AND(G25<9,G25>5),normuren!$B$10,normuren!$B$11))) -> 30 | L25: =normuren!$B$24*2*12 -> 36 | M25: =normuren!$B$25*2*12 -> 45.6 | N25: =normuren!$B$29 -> 1.5 | O25: 3 | BM25: =SUM(O25:BL25) -> 3 | BN25: =G25-BM25 -> 0 | BO25: =IF(BN25>0,"Problem","Oke") -> Oke
A26: HUM3043 | B26: Acts of Literature: The Role of Prose, Poetry, and Plays in a Changing World | C26: FASOS | D26: J. de Roder | E26: 22 | F26: =E26/12 -> 1.8333333 | G26: 2 | H26: =IF(G26=0,0,E26/G26) -> 11 | J26: =I26*2*normuren!$B$26 -> 0 | K26: =IF(G26<3,normuren!$B$8,IF(AND(G26<6,G26>2),normuren!$B$9,IF(AND(G26<9,G26>5),normuren!$B$10,normuren!$B$11))) -> 15 | L26: =normuren!$B$24*2*12 -> 36 | M26: =normuren!$B$25*2*12 -> 45.6 | N26: =normuren!$B$29 -> 1.5 | BM26: =SUM(O26:BL26) -> 0 | BN26: =G26-BM26 -> 2 | BO26: =IF(BN26>0,"Problem","Oke") -> Problem
A27: HUM3052 | B27: Lifting the Iron Curtain Modern and Contemporary Eastern Europe | C27: FASOS | D27: F. Laczó | E27: 36 | F27: =E27/12 -> 3 | G27: =ROUNDUP(F27,0) -> 3 | H27: =IF(G27=0,0,E27/G27) -> 12 | J27: =I27*2*normuren!$B$26 -> 0 | K27: =IF(G27<3,normuren!$B$8,IF(AND(G27<6,G27>2),normuren!$B$9,IF(AND(G27<9,G27>5),normuren!$B$10,normuren!$B$11))) -> 30 | L27: =normuren!$B$24*2*12 -> 36 | M27: =normuren!$B$25*2*12 -> 45.6 | N27: =normuren!$B$29 -> 1.5 | BM27: =SUM(O27:BL27) -> 0 | BN27: =G27-BM27 -> 3 | BO27: =IF(BN27>0,"Problem","Oke") -> Problem
A28: SCI1010 | B28: Basic Mathematical Tools | C28: DKE | D28: D. Vermeulen | E28: 27 | F28: =E28/13 -> 2.0769231 | G28: =ROUNDUP(F28,0) -> 3 | H28: =IF(G28=0,0,E28/G28) -> 9 | J28: =I28*2*normuren!$B$26 -> 0 | K28: =IF(G28<3,normuren!$B$8,IF(AND(G28<6,G28>2),normuren!$B$9,IF(AND(G28<9,G28>5),normuren!$B$10,normuren!$B$11))) -> 30 | L28: =normuren!$B$24*2*12 -> 36 | M28: =normuren!$B$25*2*12 -> 45.6 | N28: =normuren!$B$29 -> 1.5 | BM28: =SUM(O28:BL28) -> 0 | BN28: =G28-BM28 -> 3 | BO28: =IF(BN28>0,"Problem","Oke") -> Problem
A29: SCI2002 | B29: Discrete Mathematics | C29: DKE | D29: O. d'Huys | E29: 18 | F29: =E29/12 -> 1.5 | G29: 2 | H29: =IF(G29=0,0,E29/G29) -> 9 | J29: =I29*2*normuren!$B$26 -> 0 | K29: =IF(G29<3,normuren!$B$8,IF(AND(G29<6,G29>2),normuren!$B$9,IF(AND(G29<9,G29>5),normuren!$B$10,normuren!$B$11))) -> 15 | L29: =normuren!$B$24*2*12 -> 36 | M29: =normuren!$B$25*2*12 -> 45.6 | N29: =normuren!$B$29 -> 1.5 | BM29: =SUM(O29:BL29) -> 0 | BN29: =G29-BM29 -> 2 | BO29: =IF(BN29>0,"Problem","Oke") -> Problem
A30: SCI2011 | B30: Introduction to Programming | C30: DKE | D30: C. Browne / M. Stephenson | E30: 34 | F30: =E30/12 -> 2.8333333 | G30: 3 | H30: =IF(G30=0,0,E30/G30) -> 11.333333 | J30: =I30*2*normuren!$B$26 -> 0 | K30: =IF(G30<3,normuren!$B$8,IF(AND(G30<6,G30>2),normuren!$B$9,IF(AND(G30<9,G30>5),normuren!$B$10,normuren!$B$11))) -> 30 | L30: =normuren!$B$24*2*12 -> 36 | M30: =normuren!$B$25*2*12 -> 45.6 | N30: =normuren!$B$29 -> 1.5 | BM30: =SUM(O30:BL30) -> 0 | BN30: =G30-BM30 -> 3 | BO30: =IF(BN30>0,"Problem","Oke") -> Problem
A31: SCI2022 | B31: Genetics and Evolution | C31: FPN | D31: W. Voncken/ Co coord. B. Schmitz | E31: 32 | F31: =E31/12 -> 2.6666667 | G31: 3 | H31: =IF(G31=0,0,E31/G31) -> 10.666667 | J31: =I31*2*normuren!$B$26 -> 0 | K31: =IF(G31<3,normuren!$B$8,IF(AND(G31<6,G31>2),normuren!$B$9,IF(AND(G31<9,G31>5),normuren!$B$10,normuren!$B$11))) -> 30 | L31: =normuren!$B$24*2*12 -> 36 | M31: =normuren!$B$25*2*12 -> 45.6 | N31: =normuren!$B$29 -> 1.5 | O31: X | AO31: X | BM31: =SUM(O31:BL31) -> 0 | BN31: =G31-BM31 -> 3 | BO31: =IF(BN31>0,"Problem","Oke") -> Problem
A32: SCI3003 | B32: Optimization | C32: DKE | D32: G. Stamoulis | E32: 27 | F32: =E32/12 -> 2.25 | G32: =ROUNDUP(F32,0) -> 3 | H32: =IF(G32=0,0,E32/G32) -> 9 | J32: =I32*2*normuren!$B$26 -> 0 | K32: =IF(G32<3,normuren!$B$8,IF(AND(G32<6,G32>2),normuren!$B$9,IF(AND(G32<9,G32>5),normuren!$B$10,normuren!$B$11))) -> 30 | L32: =normuren!$B$27 -> 20 | M32: 20 | N32: =normuren!$B$29 -> 1.5 | BM32: =SUM(O32:BL32) -> 0 | BN32: =G32-BM32 -> 3 | BO32: =IF(BN32>0,"Problem","Oke") -> Problem
A33: SCI3007 | B33: Endocrinology | C33: FHML | D33: A. Gilde | E33: 49 | F33: =E33/12 -> 4.0833333 | G33: 4 | H33: =IF(G33=0,0,E33/G33) -> 12.25 | J33: =I33*2*normuren!$B$26 -> 0 | K33: =IF(G33<3,normuren!$B$8,IF(AND(G33<6,G33>2),normuren!$B$9,IF(AND(G33<9,G33>5),normuren!$B$10,normuren!$B$11))) -> 30 | L33: =normuren!$B$27 -> 20 | M33: 20 | N33: =normuren!$B$29 -> 1.5 | AO33: X | BM33: =SUM(O33:BL33) -> 0 | BN33: =G33-BM33 -> 4 | BO33: =IF(BN33>0,"Problem","Oke") -> Problem
A34: SKI2088 | B34: Lab Skills: Genetics | C34: FHML | D34: J. Broers | E34: 23 | F34: =E34/12 -> 1.9166667 | G34: =ROUNDUP(F34,0) -> 2 | H34: =IF(G34=0,0,E34/G34) -> 11.5 | J34: =I34*2*normuren!$B$26 -> 0 | K34: =IF(G34<3,normuren!$B$8,IF(AND(G34<6,G34>2),normuren!$B$9,IF(AND(G34<9,G34>5),normuren!$B$10,normuren!$B$11))) -> 15 | L34: =normuren!$B$24*2*12 -> 36 | M34: =normuren!$B$25*2*12 -> 45.6 | N34: =normuren!$B$29 -> 1.5 | BM34: =SUM(O34:BL34) -> 0 | BN34: =G34-BM34 -> 2 | BO34: =IF(BN34>0,"Problem","Oke") -> Problem
A35: SSC1005 | B35: Introduction to Psychology | C35: FPN | D35: Max Colombi | E35: 99 | F35: =E35/12 -> 8.25 | G35: 9 | H35: =IF(G35=0,0,E35/G35) -> 11 | J35: =I35*2*normuren!$B$26 -> 0 | K35: =IF(G35<3,normuren!$B$8,IF(AND(G35<6,G35>2),normuren!$B$9,IF(AND(G35<9,G35>5),normuren!$B$10,normuren!$B$11))) -> 60 | L35: =normuren!$B$24*2*12 -> 36 | M35: =normuren!$B$25*2*12 -> 45.6 | N35: =normuren!$B$29 -> 1.5 | O35: 8 | Z35: X? | BH35: 2 | BM35: =SUM(O35:BL35) -> 10 | BN35: =G35-BM35 -> -1 | BO35: =IF(BN35>0,"Problem","Oke") -> Oke
A36: SSC1007 | B36: Introduction to Law and legal Reasoning | C36: LAW | D36: G. Arosemena | E36: 60 | F36: =E36/12 -> 5 | G36: 5 | H36: =IF(G36=0,0,E36/G36) -> 12 | J36: =I36*2*normuren!$B$26 -> 0 | K36: =IF(G36<3,normuren!$B$8,IF(AND(G36<6,G36>2),normuren!$B$9,IF(AND(G36<9,G36>5),normuren!$B$10,normuren!$B$11))) -> 30 | L36: =normuren!$B$24*2*12 -> 36 | M36: =normuren!$B$25*2*12 -> 45.6 | N36: =normuren!$B$29 -> 1.5 | BM36: =SUM(O36:BL36) -> 0 | BN36: =G36-BM36 -> 5 | BO36: =IF(BN36>0,"Problem","Oke") -> Problem
A37: SSC2002 | B37: International Relations: Themes and Theories | C37: LAW | D37: B. Erdogan | E37: 27 | F37: =E37/12 -> 2.25 | G37: =ROUNDUP(F37,0) -> 3 | H37: =IF(G37=0,0,E37/G37) -> 9 | J37: =I37*2*normuren!$B$26 -> 0 | K37: =IF(G37<3,normuren!$B$8,IF(AND(G37<6,G37>2),normuren!$B$9,IF(AND(G37<9,G37>5),normuren!$B$10,normuren!$B$11))) -> 30 | L37: =normuren!$B$24*2*12 -> 36 | M37: =normuren!$B$25*2*12 -> 45.6 | N37: =normuren!$B$29 -> 1.5 | O37: 3 | BM37: =SUM(O37:BL37) -> 3 | BN37: =G37-BM37 -> 0 | BO37: =IF(BN37>0,"Problem","Oke") -> Oke
A38: SSC2020 | B38: The Economics of Information | C38: SBE | D38: S. Terstiege | E38: 23 | F38: =E38/12 -> 1.9166667 | G38: 2 | H38: =IF(G38=0,0,E38/G38) -> 11.5 | J38: =I38*2*normuren!$B$26 -> 0 | K38: =IF(G38<3,normuren!$B$8,IF(AND(G38<6,G38>2),normuren!$B$9,IF(AND(G38<9,G38>5),normuren!$B$10,normuren!$B$11))) -> 15 | L38: =normuren!$B$24*2*12 -> 36 | M38: =normuren!$B$25*2*12 -> 45.6 | N38: =normuren!$B$29 -> 1.5 | BM38: =SUM(O38:BL38) -> 0 | BN38: =G38-BM38 -> 2 | BO38: =IF(BN38>0,"Problem","Oke") -> Problem
A39: SSC2046 | B39: Globalization and Inequality: Perspectives on Development | C39: FASOS | D39: W. Nauta | E39: 90 | F39: =E39/12 -> 7.5 | G39: 9 | H39: =IF(G39=0,0,E39/G39) -> 10 | J39: =I39*2*normuren!$B$26 -> 0 | K39: =IF(G39<3,normuren!$B$8,IF(AND(G39<6,G39>2),normuren!$B$9,IF(AND(G39<9,G39>5),normuren!$B$10,normuren!$B$11))) -> 60 | L39: =normuren!$B$24*2*12 -> 36 | M39: =normuren!$B$25*2*12 -> 45.6 | N39: =normuren!$B$29 -> 1.5 | BM39: =SUM(O39:BL39) -> 0 | BN39: =G39-BM39 -> 9 | BO39: =IF(BN39>0,"Problem","Oke") -> Problem
A40: SSC2063 | B40: The Psychology of Individual Differences | C40: FPN | D40: P. Brüll | E40: 62 | F40: =E40/12 -> 5.1666667 | G40: 5 | H40: =IF(G40=0,0,E40/G40) -> 12.4 | J40: =I40*2*normuren!$B$26 -> 0 | K40: =IF(G40<3,normuren!$B$8,IF(AND(G40<6,G40>2),normuren!$B$9,IF(AND(G40<9,G40>5),normuren!$B$10,normuren!$B$11))) -> 30 | L40: =normuren!$B$24*2*12 -> 36 | M40: =normuren!$B$25*2*12 -> 45.6 | N40: =normuren!$B$29 -> 1.5 | O40: 5 | BF40: 0 | BM40: =SUM(O40:BL40) -> 5 | BN40: =G40-BM40 -> 0 | BO40: =IF(BN40>0,"Problem","Oke") -> Oke
A41: SSC3006 | B41: The Social Study of Environmental Problems: Between Nature, Society, and Politics | C41: FASOS | D41: J. Lachmund | E41: 77 | F41: =E41/12 -> 6.4166667 | G41: =ROUNDUP(F41,0) -> 7 | H41: =IF(G41=0,0,E41/G41) -> 11 | J41: =I41*2*normuren!$B$26 -> 0 | K41: =IF(G41<3,normuren!$B$8,IF(AND(G41<6,G41>2),normuren!$B$9,IF(AND(G41<9,G41>5),normuren!$B$10,normuren!$B$11))) -> 45 | L41: =normuren!$B$24*2*12 -> 36 | M41: =normuren!$B$25*2*12 -> 45.6 | N41: =normuren!$B$29 -> 1.5 | BM41: =SUM(O41:BL41) -> 0 | BN41: =G41-BM41 -> 7 | BO41: =IF(BN41>0,"Problem","Oke") -> Problem
...

Sheet PERIOD 2
A1: PERIOD 2 | K1: Hours | AU1: Junior Lecturers (D4) & OBP | AV1: Junior Lecturers (D4) & OBP
A2: CODE | B2: COURSE TITLE | C2: Faculty | D2: COORDINATOR | E2: NR | F2: TG | G2: TG | H2: ST/TG | I2: Lect | J2: lect | K2: Coor | L2: per TG regular staff | M2: Per TG 1st Year JTF | N2: Per ST | O2: FAC | P2: Lbe | Q2: LB | R2: Sca | S2: TD | T2: WvD | U2: CE | V2: AF | W2: WG | X2: TG | Y2: RH | Z2: CH | AA2: KH | AB2: MH | AC2: MK | AD2: VL | AE2: EM | AF2: DM | AG2: JM | AH2: UM | AI2: LO | AJ2: AO | AK2: JvP | AL2: CR | AM2: IR | AN2: JS | AO2: BS | AP2: MS | AQ2: PV | AR2: DV | AS2: JW | AT2: AW | AU2: CYPL | AV2: JB/OBP | AW2: SB/D4 | AX2: CC/OBP | AY2: XT/D4 | AZ2: RvE/D4 | BA2: ZE/OBP | BB2: CD/D4 | BC2: JH/D4 | BD2: WH/D4 | BE2: JvL/D4 | BF2: IM/D4 | BG2: APT/D4 | BH2: WS/D4 | BI2: KK/D4 | BJ2: MM/D4 | BK2: JvZ/D4 | BL2: WOS/OBP | BM2: Total | BN2: TG problem
A4: CAP3000 | B4: Capstone | C4: UCM | D4: J. Moes/ E. Maegherman | F4: =E4/12 -> 0 | H4: =IF(G4=0,0,E4/G4) -> 0 | P4: X | T4: 1 | X4: X | Y4: ? | AD4: 1 | AE4: X | AG4: 1 | AL4: 1 | AN4: X | AR4: X | AS4: X | AT4: X | AU4: 1
A5: COR1002 | B5: Philosophy of Science | C5: UCM | D5: P. Vermeer | F5: =E5/12 -> 0 | H5: =IF(G5=0,0,E5/G5) -> 0 | J5: =I5*2*normuren!$B$26 -> 0 | K5: =IF(G5<3,normuren!$B$8,IF(AND(G5<6,G5>2),normuren!$B$9,IF(AND(G5<9,G5>5),normuren!$B$10,normuren!$B$11))) -> 15 | L5: =normuren!$B$24*2*12 -> 36 | M5: =normuren!$B$25*2*12 -> 45.6 | N5: =normuren!$B$29 -> 1.5 | O5: X | X5: X | AQ5: 1 | AX5: X | BC5: 3 | BM5: =SUM(O5:BL5) -> 4 | BN5: =G5-BM5 -> -4 | BO5: =IF(BN5>0,"Problem","Oke") -> Oke | BP5: FP; zeta/ceren
A6: COR1004 | B6: Political Philosophy | C6: FASOS | D6: J. Prinz | F6: =$E6/12 -> 0 | G6: =ROUNDUP(F6,0) -> 0 | H6: =IF(G6=0,0,E6/G6) -> 0 | J6: =I6*2*normuren!$B$26 -> 0 | K6: =IF(G6<3,normuren!$B$8,IF(AND(G6<6,G6>2),normuren!$B$9,IF(AND(G6<9,G6>5),normuren!$B$10,normuren!$B$11))) -> 15 | L6: =normuren!$B$27 -> 20 | M6: 20 | N6: =normuren!$B$29 -> 1.5 | O6: X | BM6: =SUM(O6:BL6) -> 0 | BN6: =G6-BM6 -> 0 | BO6: =IF(BN6>0,"Problem","Oke") -> Oke | BP6: CH, 1-2 TG's Global Studies
A7: HUM1010 | B7: Common Foundations of Law in Europe | C7: LAW | D7: R. van Rhee | F7: =E7/12 -> 0 | G7: =ROUNDUP(F7,0) -> 0 | H7: =IF(G7=0,0,E7/G7) -> 0 | J7: =I7*2*normuren!$B$26 -> 0 | K7: =IF(G7<3,normuren!$B$8,IF(AND(G7<6,G7>2),normuren!$B$9,IF(AND(G7<9,G7>5),normuren!$B$10,normuren!$B$11))) -> 15 | L7: =normuren!$B$24*2*12 -> 36 | M7: =normuren!$B$25*2*12 -> 45.6 | N7: =normuren!$B$29 -> 1.5 | BM7: =SUM(O7:BL7) -> 0 | BN7: =G7-BM7 -> 0 | BO7: =IF(BN7>0,"Problem","Oke") -> Oke
A8: HUM1013 | B8: The Idea of Europe: The Intellectual History of Europe | C8: UCM | D8: M. Stout | F8: =E8/12 -> 0 | G8: =ROUNDUP(F8,0) -> 0 | H8: =IF(G8=0,0,E8/G8) -> 0 | J8: =I8*2*normuren!$B$26 -> 0 | K8: =IF(G8<3,normuren!$B$8,IF(AND(G8<6,G8>2),normuren!$B$9,IF(AND(G8<9,G8>5),normuren!$B$10,normuren!$B$11))) -> 15 | L8: =normuren!$B$27 -> 20 | M8: 20 | N8: =normuren!$B$29 -> 1.5 | Q8: Max 1 | AP8: 3 | BM8: =SUM(O8:BL8) -> 3 | BN8: =G8-BM8 -> -3 | BO8: =IF(BN8>0,"Problem","Oke") -> Oke
A9: HUM2013 | B9: The Presence of Art: Reinterpreting Modern and Contemporary Art | C9: UCM | D9: C. Rausch - > I. Romgens | F9: =E9/12 -> 0 | G9: =ROUNDUP(F9,0) -> 0 | H9: =IF(G9=0,0,E9/G9) -> 0 | J9: =I9*2*normuren!$B$26 -> 0 | K9: =IF(G9<3,normuren!$B$8,IF(AND(G9<6,G9>2),normuren!$B$9,IF(AND(G9<9,G9>5),normuren!$B$10,normuren!$B$11))) -> 15 | L9: =normuren!$B$24*2*12 -> 36 | M9: =normuren!$B$25*2*12 -> 45.6 | N9: =normuren!$B$29 -> 1.5 | O9: X | AM9: 2 | BE9: 2 | BM9: =SUM(O9:BL9) -> 4 | BN9: =G9-BM9 -> -4 | BO9: =IF(BN9>0,"Problem","Oke") -> Oke
A10: HUM2022 | B10: Digital Media: Digitalization, Digital Cultures and User Practices | C10: FASOS | D10: J. de Roder | F10: =E10/12 -> 0 | G10: =ROUNDUP(F10,0) -> 0 | H10: =IF(G10=0,0,E10/G10) -> 0 | J10: =I10*2*normuren!$B$26 -> 0 | K10: =IF(G10<3,normuren!$B$8,IF(AND(G10<6,G10>2),normuren!$B$9,IF(AND(G10<9,G10>5),normuren!$B$10,normuren!$B$11))) -> 15 | L10: =normuren!$B$24*2*12 -> 36 | M10: =normuren!$B$25*2*12 -> 45.6 | N10: =normuren!$B$29 -> 1.5 | BM10: =SUM(O10:BL10) -> 0 | BN10: =G10-BM10 -> 0 | BO10: =IF(BN10>0,"Problem","Oke") -> Oke
A11: HUM2057 | B11: Religion, Myth and Secularization | C11: FASOS | D11: M. Kardaun | F11: =E11/12 -> 0 | G11: =ROUNDUP(F11,0) -> 0 | H11: =IF(G11=0,0,E11/G11) -> 0 | J11: =I11*2*normuren!$B$26 -> 0 | K11: =IF(G11<3,normuren!$B$8,IF(AND(G11<6,G11>2),normuren!$B$9,IF(AND(G11<9,G11>5),normuren!$B$10,normuren!$B$11))) -> 15 | L11: =normuren!$B$24*2*12 -> 36 | M11: =normuren!$B$25*2*12 -> 45.6 | N11: =normuren!$B$29 -> 1.5 | O11: X | BM11: =SUM(O11:BL11) -> 0 | BN11: =G11-BM11 -> 0 | BO11: =IF(BN11>0,"Problem","Oke") -> Oke
A12: HUM2059 | B12: Data Analysis and Visualisation for the Humanities and Social Sciences | C12: FASOS | D12: S. Schreibman/C. Papadopoulos | F12: =E12/12 -> 0 | G12: =ROUNDUP(F12,0) -> 0 | H12: =IF(G12=0,0,E12/G12) -> 0 | J12: =I12*2*normuren!$B$26 -> 0 | K12: =IF(G12<3,normuren!$B$8,IF(AND(G12<6,G12>2),normuren!$B$9,IF(AND(G12<9,G12>5),normuren!$B$10,normuren!$B$11))) -> 15 | L12: =normuren!$B$24*2*12 -> 36 | M12: =normuren!$B$25*2*12 -> 45.6 | N12: =normuren!$B$29 -> 1.5 | BM12: =SUM(O12:BL12) -> 0 | BN12: =G12-BM12 -> 0 | BO12: =IF(BN12>0,"Problem","Oke") -> Oke
A13: HUM2060 | B13: Poetry, Poetry Theory and Poetry Practices | C13: FASOS | D13: J. de Roder | F13: =E13/12 -> 0 | G13: =ROUNDUP(F13,0) -> 0 | H13: =IF(G13=0,0,E13/G13) -> 0 | J13: =I13*2*normuren!$B$26 -> 0 | K13: =IF(G13<3,normuren!$B$8,IF(AND(G13<6,G13>2),normuren!$B$9,IF(AND(G13<9,G13>5),normuren!$B$10,normuren!$B$11))) -> 15 | L13: =normuren!$B$24*2*12 -> 36 | M13: =normuren!$B$25*2*12 -> 45.6 | N13: =normuren!$B$29 -> 1.5 | BM13: =SUM(O13:BL13) -> 0 | BN13: =G13-BM13 -> 0 | BO13: =IF(BN13>0,"Problem","Oke") -> Oke
A14: HUM3014 | B14: Philosophers of the 20th Century | C14: FASOS | D14: R. Gabriels | F14: =E14/12 -> 0 | G14: =ROUNDUP(F14,0) -> 0 | H14: =IF(G14=0,0,E14/G14) -> 0 | J14: =I14*2*normuren!$B$26 -> 0 | K14: =IF(G14<3,normuren!$B$8,IF(AND(G14<6,G14>2),normuren!$B$9,IF(AND(G14<9,G14>5),normuren!$B$10,normuren!$B$11))) -> 15 | L14: =normuren!$B$24*2*12 -> 36 | M14: =normuren!$B$25*2*12 -> 45.6 | N14: =normuren!$B$29 -> 1.5 | BM14: =SUM(O14:BL14) -> 0 | BN14: =G14-BM14 -> 0 | BO14: =IF(BN14>0,"Problem","Oke") -> Oke
A15: HUM3040 | B15: Crucial Differences in the 21st Century | C15: FASOS | D15: L. van den Hengel | F15: =E15/12 -> 0 | G15: =ROUNDUP(F15,0) -> 0 | H15: =IF(G15=0,0,E15/G15) -> 0 | J15: =I15*2*normuren!$B$26 -> 0 | K15: =IF(G15<3,normuren!$B$8,IF(AND(G15<6,G15>2),normuren!$B$9,IF(AND(G15<9,G15>5),normuren!$B$10,normuren!$B$11))) -> 15 | L15: =normuren!$B$24*2*12 -> 36 | M15: =normuren!$B$25*2*12 -> 45.6 | N15: =normuren!$B$29 -> 1.5 | BD15: X | BM15: =SUM(O15:BL15) -> 0 | BN15: =G15-BM15 -> 0 | BO15: =IF(BN15>0,"Problem","Oke") -> Oke
A16: HUM3049 | B16: Science and Technology Studies 2: Science, Power and Construction of Facts | C16: FASOS | D16: J. Mesman | F16: =E16/12 -> 0 | G16: =ROUNDUP(F16,0) -> 0 | H16: =IF(G16=0,0,E16/G16) -> 0 | J16: =I16*2*normuren!$B$26 -> 0 | K16: =IF(G16<3,normuren!$B$8,IF(AND(G16<6,G16>2),normuren!$B$9,IF(AND(G16<9,G16>5),normuren!$B$10,normuren!$B$11))) -> 15 | L16: =normuren!$B$24*2*12 -> 36 | M16: =normuren!$B$25*2*12 -> 45.6 | N16: =normuren!$B$29 -> 1.5 | BM16: =SUM(O16:BL16) -> 0 | BN16: =G16-BM16 -> 0 | BO16: =IF(BN16>0,"Problem","Oke") -> Oke
A17: HUM3050 | B17: A Cultural Critique of Our Aging Society | C17: FASOS | D17: A. Swinnen | F17: =E17/12 -> 0 | G17: =ROUNDUP(F17,0) -> 0 | H17: =IF(G17=0,0,E17/G17) -> 0 | J17: =I17*2*normuren!$B$26 -> 0 | K17: =IF(G17<3,normuren!$B$8,IF(AND(G17<6,G17>2),normuren!$B$9,IF(AND(G17<9,G17>5),normuren!$B$10,normuren!$B$11))) -> 15 | L17: =normuren!$B$24*2*12 -> 36 | M17: =normuren!$B$25*2*12 -> 45.6 | N17: =normuren!$B$29 -> 1.5 | BM17: =SUM(O17:BL17) -> 0 | BN17: =G17-BM17 -> 0 | BO17: =IF(BN17>0,"Problem","Oke") -> Oke
A18: HUM3053 | B18: The Idea of Africa | C18: UCM/FASOS | D18: U. Müller / T. Makori | F18: =E18/12 -> 0 | G18: =ROUNDUP(F18,0) -> 0 | H18: =IF(G18=0,0,E18/G18) -> 0 | J18: =I18*2*normuren!$B$26 -> 0 | K18: =IF(G18<3,normuren!$B$8,IF(AND(G18<6,G18>2),normuren!$B$9,IF(AND(G18<9,G18>5),normuren!$B$10,normuren!$B$11))) -> 15 | L18: =normuren!$B$24*2*12 -> 36 | M18: =normuren!$B$25*2*12 -> 45.6 | N18: =normuren!$B$29 -> 1.5 | AH18: 1 | BE18: X | BM18: =SUM(O18:BL18) -> 1 | BN18: =G18-BM18 -> -1 | BO18: =IF(BN18>0,"Problem","Oke") -> Oke
A19: SCI1004 | B19: Introduction to Chemistry | C19: MSP | D19: C. Bahn | F19: =E19/12 -> 0 | G19: =ROUNDUP(F19,0) -> 0 | H19: =IF(G19=0,0,E19/G19) -> 0 | J19: =I19*2*normuren!$B$26 -> 0 | K19: =IF(G19<3,normuren!$B$8,IF(AND(G19<6,G19>2),normuren!$B$9,IF(AND(G19<9,G19>5),normuren!$B$10,normuren!$B$11))) -> 15 | L19: =normuren!$B$24*2*12 -> 36 | M19: =normuren!$B$25*2*12 -> 45.6 | N19: =normuren!$B$29 -> 1.5 | O19: X | BM19: =SUM(O19:BL19) -> 0 | BN19: =G19-BM19 -> 0 | BO19: =IF(BN19>0,"Problem","Oke") -> Oke
A20: SCI1005 | B20: The Digital Enterprise | C20: SBE | D20: F. Harmsen | F20: =E20/12 -> 0 | G20: =ROUNDUP(F20,0) -> 0 | H20: =IF(G20=0,0,E20/G20) -> 0 | J20: =I20*2*normuren!$B$26 -> 0 | K20: =IF(G20<3,normuren!$B$8,IF(AND(G20<6,G20>2),normuren!$B$9,IF(AND(G20<9,G20>5),normuren!$B$10,normuren!$B$11))) -> 15 | L20: =normuren!$B$24*2*12 -> 36 | M20: =normuren!$B$25*2*12 -> 45.6 | N20: =normuren!$B$29 -> 1.5 | BM20: =SUM(O20:BL20) -> 0 | BN20: =G20-BM20 -> 0 | BO20: =IF(BN20>0,"Problem","Oke") -> Oke
A21: SCI1016 | B21: Sustainable Development | C21: MSI | D21: M. Huynen | F21: =E21/12 -> 0 | G21: =ROUNDUP(F21,0) -> 0 | H21: =IF(G21=0,0,E21/G21) -> 0 | J21: =I21*2*normuren!$B$26 -> 0 | K21: =IF(G21<3,normuren!$B$8,IF(AND(G21<6,G21>2),normuren!$B$9,IF(AND(G21<9,G21>5),normuren!$B$10,normuren!$B$11))) -> 15 | L21: =normuren!$B$27 -> 20 | M21: 20 | N21: =normuren!$B$29 -> 1.5 | O21: X | BM21: =SUM(O21:BL21) -> 0 | BN21: =G21-BM21 -> 0 | BO21: =IF(BN21>0,"Problem","Oke") -> Oke
A22: SCI2018 | B22: Calculus | C22: DKE | D22: G. Schoenmakers | F22: =E22/12 -> 0 | G22: =ROUNDUP(F22,0) -> 0 | H22: =IF(G22=0,0,E22/G22) -> 0 | J22: =I22*2*normuren!$B$26 -> 0 | K22: =IF(G22<3,normuren!$B$8,IF(AND(G22<6,G22>2),normuren!$B$9,IF(AND(G22<9,G22>5),normuren!$B$10,normuren!$B$11))) -> 15 | L22: =normuren!$B$27 -> 20 | M22: 20 | N22: =normuren!$B$29 -> 1.5 | BM22: =SUM(O22:BL22) -> 0 | BN22: =G22-BM22 -> 0 | BO22: =IF(BN22>0,"Problem","Oke") -> Oke
A23: SCI2034 | B23: Functional Neuroanatomy | C23: UCM | D23: M. Heins | F23: =E23/12 -> 0 | G23: =ROUNDUP(F23,0) -> 0 | H23: =IF(G23=0,0,E23/G23) -> 0 | J23: =I23*2*normuren!$B$26 -> 0 | K23: =IF(G23<3,normuren!$B$8,IF(AND(G23<6,G23>2),normuren!$B$9,IF(AND(G23<9,G23>5),normuren!$B$10,normuren!$B$11))) -> 15 | L23: =normuren!$B$27 -> 20 | M23: 20 | N23: =normuren!$B$29 -> 1.5 | AO23: X | AX23: 3 | BM23: =SUM(O23:BL23) -> 3 | BN23: =G23-BM23 -> -3 | BO23: =IF(BN23>0,"Problem","Oke") -> Oke
A24: SCI2035 | B24: Biochemistry | C24: FHML | D24: N. Deckers / C. Reutelingsperger | F24: =E24/12 -> 0 | G24: =ROUNDUP(F24,0) -> 0 | H24: =IF(G24=0,0,E24/G24) -> 0 | J24: =I24*2*normuren!$B$26 -> 0 | K24: =IF(G24<3,normuren!$B$8,IF(AND(G24<6,G24>2),normuren!$B$9,IF(AND(G24<9,G24>5),normuren!$B$10,normuren!$B$11))) -> 15 | L24: =normuren!$B$27 -> 20 | M24: 20 | N24: =normuren!$B$29 -> 1.5 | BM24: =SUM(O24:BL24) -> 0 | BN24: =G24-BM24 -> 0 | BO24: =IF(BN24>0,"Problem","Oke") -> Oke
A25: SCI2036 | B25: Artificial intelligence | C25: DKE | D25: S. Asteriadis | F25: =E25/12 -> 0 | G25: =ROUNDUP(F25,0) -> 0 | H25: =IF(G25=0,0,E25/G25) -> 0 | J25: =I25*2*normuren!$B$26 -> 0 | K25: =IF(G25<3,normuren!$B$8,IF(AND(G25<6,G25>2),normuren!$B$9,IF(AND(G25<9,G25>5),normuren!$B$10,normuren!$B$11))) -> 15 | L25: =normuren!$B$27 -> 20 | M25: 20 | N25: =normuren!$B$29 -> 1.5 | BM25: =SUM(O25:BL25) -> 0 | BN25: =G25-BM25 -> 0 | BO25: =IF(BN25>0,"Problem","Oke") -> Oke
A26: SCI3005 | B26: Metabolism, Nutrition and Exercise | C26: FHML | D26: J. Hoeks | F26: =E26/12 -> 0 | G26: =ROUNDUP(F26,0) -> 0 | H26: =IF(G26=0,0,E26/G26) -> 0 | J26: =I26*2*normuren!$B$26 -> 0 | K26: =IF(G26<3,normuren!$B$8,IF(AND(G26<6,G26>2),normuren!$B$9,IF(AND(G26<9,G26>5),normuren!$B$10,normuren!$B$11))) -> 15 | L26: =normuren!$B$27 -> 20 | M26: 20 | N26: =normuren!$B$29 -> 1.5 | BM26: =SUM(O26:BL26) -> 0 | BN26: =G26-BM26 -> 0 | BO26: =IF(BN26>0,"Problem","Oke") -> Oke
A27: SCI3050 | B27: Advances in Biomedical Sciences | C27: FHML | D27: P. Wieringa | F27: =E27/12 -> 0 | G27: =ROUNDUP(F27,0) -> 0 | H27: =IF(G27=0,0,E27/G27) -> 0 | J27: =I27*2*normuren!$B$26 -> 0 | K27: =IF(G27<3,normuren!$B$8,IF(AND(G27<6,G27>2),normuren!$B$9,IF(AND(G27<9,G27>5),normuren!$B$10,normuren!$B$11))) -> 15 | L27: =normuren!$B$24*2*12 -> 36 | M27: =normuren!$B$25*2*12 -> 45.6 | N27: =normuren!$B$29 -> 1.5 | BM27: =SUM(O27:BL27) -> 0 | BN27: =G27-BM27 -> 0 | BO27: =IF(BN27>0,"Problem","Oke") -> Oke
A28: SKI1005 | B28: Research Methods II | C28: UCM | D28: J. Moes - > E. Maegherman | F28: =E28/12 -> 0 | G28: =ROUNDUP(F28,0) -> 0 | H28: =IF(G28=0,0,E28/G28) -> 0 | J28: =I28*2*normuren!$B$26 -> 0 | K28: =IF(G28<3,normuren!$B$8,IF(AND(G28<6,G28>2),normuren!$B$9,IF(AND(G28<9,G28>5),normuren!$B$10,normuren!$B$11))) -> 15 | L28: =normuren!$B$24*2*12 -> 36 | M28: =normuren!$B$25*2*12 -> 45.6 | N28: =normuren!$B$29 -> 1.5 | AE28: 1 | AG28: 1 | AX28: X | BH28: 2 | BL28: 2 | BM28: =SUM(O28:BL28) -> 6 | BN28: =G28-BM28 -> -6 | BO28: =IF(BN28>0,"Problem","Oke") -> Oke
A29: SKI1009 | B29: Introduction to Academic Skills II | C29: UCM | D29: A. Wellum / A. Foster | F29: =$E29/12 -> 0 | G29: =ROUNDUP(F29,0) -> 0 | H29: =IF(G29=0,0,E29/G29) -> 0 | J29: =I29*2*normuren!$B$26 -> 0 | K29: =IF(G29<3,normuren!$B$8,IF(AND(G29<6,G29>2),normuren!$B$9,IF(AND(G29<9,G29>5),normuren!$B$10,normuren!$B$11))) -> 15 | L29: =normuren!$B$27 -> 20 | M29: 20 | N29: =normuren!$B$29 -> 1.5 | V29: 2 | AV29: 3 | AX29: X | BC29: 2 | BD29: 2 | BE29: 3 | BI29: 2 | BJ29: X | BM29: =SUM(O29:BL29) -> 14 | BN29: =G29-BM29 -> -14 | BO29: =IF(BN29>0,"Problem","Oke") -> Oke
A30: SKI2084 | B30: Writing in an Academic Context: Improving Argumentation and Style | C30: UCM | D30: A. Wellum / A. Foster | F30: =$E30/12 -> 0 | G30: =ROUNDUP(F30,0) -> 0 | H30: =IF(G30=0,0,E30/G30) -> 0 | J30: =I30*2*normuren!$B$26 -> 0 | K30: =IF(G30<3,normuren!$B$8,IF(AND(G30<6,G30>2),normuren!$B$9,IF(AND(G30<9,G30>5),normuren!$B$10,normuren!$B$11))) -> 15 | L30: =normuren!$B$27 -> 20 | M30: 20 | N30: =normuren!$B$29 -> 1.5 | V30: NO | X30: X | AD30: 1 | AT30: 3 | AX30: 2 | BH30: 3 | BM30: =SUM(O30:BL30) -> 9 | BN30: =G30-BM30 -> -9 | BO30: =IF(BN30>0,"Problem","Oke") -> Oke
A31: SKI2086 | B31: Lab Skills: Biochemistry | C31: FHML | D31: N. Beckers | F31: =E31/12 -> 0 | G31: =ROUNDUP(F31,0) -> 0 | H31: =IF(G31=0,0,E31/G31) -> 0 | J31: =I31*2*normuren!$B$26 -> 0 | K31: =IF(G31<3,normuren!$B$8,IF(AND(G31<6,G31>2),normuren!$B$9,IF(AND(G31<9,G31>5),normuren!$B$10,normuren!$B$11))) -> 15 | L31: =normuren!$B$24*2*12 -> 36 | M31: =normuren!$B$25*2*12 -> 45.6 | N31: =normuren!$B$29 -> 1.5 | BM31: =SUM(O31:BL31) -> 0 | BN31: =G31-BM31 -> 0 | BO31: =IF(BN31>0,"Problem","Oke") -> Oke
A32: SKI3002 | B32: Argumentation II | C32: UCM | D32: P. Vermeer | F32: =E32/12 -> 0 | G32: =ROUNDUP(F32,0) -> 0 | H32: =IF(G32=0,0,E32/G32) -> 0 | J32: =I32*2*normuren!$B$26 -> 0 | K32: =IF(G32<3,normuren!$B$8,IF(AND(G32<6,G32>2),normuren!$B$9,IF(AND(G32<9,G32>5),normuren!$B$10,normuren!$B$11))) -> 15 | L32: =normuren!$B$24*2*12 -> 36 | M32: =normuren!$B$25*2*12 -> 45.6 | N32: =normuren!$B$29 -> 1.5 | AQ32: 1 | AV32: 3 | BC32: X | BD32: 2 | BJ32: X | BM32: =SUM(O32:BL32) -> 6 | BN32: =G32-BM32 -> -6 | BO32: =IF(BN32>0,"Problem","Oke") -> Oke
A33: SKI3003 | B33: Research Studio, introduction to applying an art practice as research method | C33: UCM | D33: I. Römgens | F33: =E33/12 -> 0 | G33: =ROUNDUP(F33,0) -> 0 | H33: =IF(G33=0,0,E33/G33) -> 0 | J33: =I33*2*normuren!$B$26 -> 0 | K33: =IF(G33<3,normuren!$B$8,IF(AND(G33<6,G33>2),normuren!$B$9,IF(AND(G33<9,G33>5),normuren!$B$10,normuren!$B$11))) -> 15 | L33: =normuren!$B$24*2*12 -> 36 | M33: =normuren!$B$25*2*12 -> 45.6 | N33: =normuren!$B$29 -> 1.5 | AM33: X | BM33: =SUM(O33:BL33) -> 0 | BN33: =G33-BM33 -> 0 | BO33: =IF(BN33>0,"Problem","Oke") -> Oke
A34: SKI3050 | B34: Preparing Conference | C34: UCM | D34: W. van Dellen | F34: =E34/12 -> 0 | G34: =ROUNDUP(F34,0) -> 0 | H34: =IF(G34=0,0,E34/G34) -> 0 | J34: =I34*2*normuren!$B$26 -> 0 | K34: =IF(G34<3,normuren!$B$8,IF(AND(G34<6,G34>2),normuren!$B$9,IF(AND(G34<9,G34>5),normuren!$B$10,normuren!$B$11))) -> 15 | L34: =normuren!$B$24*2*12 -> 36 | M34: =normuren!$B$25*2*12 -> 45.6 | N34: =normuren!$B$29 -> 1.5 | T34: 1 or 2 | BM34: =SUM(O34:BL34) -> 0 | BN34: =G34-BM34 -> 0 | BO34: =IF(BN34>0,"Problem","Oke") -> Oke
A35: SKI3052 | B35: Ethnography and Qualitative Interviewing II | C35: UCM | D35: U. Müller | F35: =E35/12 -> 0 | G35: =ROUNDUP(F35,0) -> 0 | H35: =IF(G35=0,0,E35/G35) -> 0 | J35: =I35*2*normuren!$B$26 -> 0 | K35: =IF(G35<3,normuren!$B$8,IF(AND(G35<6,G35>2),normuren!$B$9,IF(AND(G35<9,G35>5),normuren!$B$10,normuren!$B$11))) -> 15 | L35: =normuren!$B$24*2*12 -> 36 | M35: =normuren!$B$25*2*12 -> 45.6 | N35: =normuren!$B$29 -> 1.5 | AH35: 2 to 4 | BM35: =SUM(O35:BL35) -> 0 | BN35: =G35-BM35 -> 0 | BO35: =IF(BN35>0,"Problem","Oke") -> Oke
A36: SSC1025 | B36: Introduction to Political Science | C36: UCM | D36: R. Haar | F36: =E36/12 -> 0 | G36: =ROUNDUP(F36,0) -> 0 | H36: =IF(G36=0,0,E36/G36) -> 0 | J36: =I36*2*normuren!$B$26 -> 0 | K36: =IF(G36<3,normuren!$B$8,IF(AND(G36<6,G36>2),normuren!$B$9,IF(AND(G36<9,G36>5),normuren!$B$10,normuren!$B$11))) -> 15 | L36: =normuren!$B$24*2*12 -> 36 | M36: =normuren!$B$25*2*12 -> 45.6 | N36: =normuren!$B$29 -> 1.5 | Y36: 1 | BI36: 3 | BJ36: X? | BM36: =SUM(O36:BL36) -> 4 | BN36: =G36-BM36 -> -4 | BO36: =IF(BN36>0,"Problem","Oke") -> Oke
A37: SSC1027 | B37: Principles of Economics | C37: SBE | D37: S. Terstiege | F37: =E37/12 -> 0 | G37: =ROUNDUP(F37,0) -> 0 | H37: =IF(G37=0,0,E37/G37) -> 0 | J37: =I37*2*normuren!$B$26 -> 0 | K37: =IF(G37<3,normuren!$B$8,IF(AND(G37<6,G37>2),normuren!$B$9,IF(AND(G37<9,G37>5),normuren!$B$10,normuren!$B$11))) -> 15 | L37: =normuren!$B$24*2*12 -> 36 | M37: =normuren!$B$25*2*12 -> 45.6 | N37: =normuren!$B$29 -> 1.5 | BM37: =SUM(O37:BL37) -> 0 | BN37: =G37-BM37 -> 0 | BO37: =IF(BN37>0,"Problem","Oke") -> Oke
A38: SSC1030 | B38: Introduction to Business Administration | C38: SBE | D38: P. Bollen | F38: =E38/12 -> 0 | G38: =ROUNDUP(F38,0) -> 0 | H38: =IF(G38=0,0,E38/G38) -> 0 | J38: =I38*2*normuren!$B$26 -> 0 | K38: =IF(G38<3,normuren!$B$8,IF(AND(G38<6,G38>2),normuren!$B$9,IF(AND(G38<9,G38>5),normuren!$B$10,normuren!$B$11))) -> 15 | L38: =normuren!$B$24*2*12 -> 36 | M38: =normuren!$B$25*2*12 -> 45.6 | N38: =normuren!$B$29 -> 1.5 | O38: X | BM38: =SUM(O38:BL38) -> 0 | BN38: =G38-BM38 -> 0 | BO38: =IF(BN38>0,"Problem","Oke") -> Oke
A39: SSC2011 | B39: European Integration; History and Theory | C39: FASOS | D39: K. van Leeuwen | F39: =E39/12 -> 0 | G39: =ROUNDUP(F39,0) -> 0 | H39: =IF(G39=0,0,E39/G39) -> 0 | J39: =I39*2*normuren!$B$26 -> 0 | K39: =IF(G39<3,normuren!$B$8,IF(AND(G39<6,G39>2),normuren!$B$9,IF(AND(G39<9,G39>5),normuren!$B$10,normuren!$B$11))) -> 15 | L39: =normuren!$B$24*2*12 -> 36 | M39: =normuren!$B$25*2*12 -> 45.6 | N39: =normuren!$B$29 -> 1.5 | BM39: =SUM(O39:BL39) -> 0 | BN39: =G39-BM39 -> 0 | BO39: =IF(BN39>0,"Problem","Oke") -> Oke
A40: SSC2019 | B40: Social Psychology | C40: FPN | D40: A. van der Lugt/ M. Colombi | F40: =E40/12 -> 0 | G40: =ROUNDUP(F40,0) -> 0 | H40: =IF(G40=0,0,E40/G40) -> 0 | J40: =I40*2*normuren!$B$26 -> 0 | K40: =IF(G40<3,normuren!$B$8,IF(AND(G40<6,G40>2),normuren!$B$9,IF(AND(G40<9,G40>5),normuren!$B$10,normuren!$B$11))) -> 15 | L40: =normuren!$B$24*2*12 -> 36 | M40: =normuren!$B$25*2*12 -> 45.6 | N40: =normuren!$B$29 -> 1.5 | BM40: =SUM(O40:BL40) -> 0 | BN40: =G40-BM40 -> 0 | BO40: =IF(BN40>0,"Problem","Oke") -> Oke
A41: SSC2024 | B41: International Law | C41: LAW | D41: I. Westendorp | F41: =E41/12 -> 0 | G41: =ROUNDUP(F41,0) -> 0 | H41: =IF(G41=0,0,E41/G41) -> 0 | J41: =I41*2*normuren!$B$26 -> 0 | K41: =IF(G41<3,normuren!$B$8,IF(AND(G41<6,G41>2),normuren!$B$9,IF(AND(G41<9,G41>5),normuren!$B$10,normuren!$B$11))) -> 15 | L41: =normuren!$B$24*2*12 -> 36 | M41: =normuren!$B$25*2*12 -> 45.6 | N41: =normuren!$B$29 -> 1.5 | BM41: =SUM(O41:BL41) -> 0 | BN41: =G41-BM41 -> 0 | BO41: =IF(BN41>0,"Problem","Oke") -> Oke
...

Sheet PERIOD 3
A1: PERIOD 3 | K1: Hours | AT1: Junior Lecturers (D4) & OBP | AU1: Junior Lecturers (D4) & OBP
A2: CODE | B2: COURSE TITLE | C2: Faculty | D2: COORDINATOR | E2: NR | F2: TG | G2: TG | H2: ST/TG | I2: Lect | J2: lect | K2: Coor | L2: per TG regular staff | M2: Per TG 1st Year JTF | N2: Per ST | O2: FAC | P2: Lbe | Q2: LB | R2: Sca | S2: TD | T2: WvD | U2: CE | V2: AF | W2: WG | X2: TG | Y2: RH | Z2: CH | AA2: KH | AB2: MH | AC2: MK | AD2: VL | AE2: EM | AF2: DM | AG2: JM | AH2: UM | AI2: AO | AJ2: JvP | AK2: CR | AL2: IR | AM2: JS | AN2: BS | AO2: MS | AP2: PV | AQ2: DV | AR2: JW | AS2: AW | AT2: CYPL | AU2: JB/OBP | AV2: SB/D4 | AW2: CC/OBP | AX2: XT/D4 | AY2: RvE/D4 | AZ2: ZE/OBP | BA2: CG/D4 | BB2: JH/D4 | BC2: WH/D4 | BD2: JvL/D4 | BE2: IM/D4 | BF2: APT/D4 | BG2: WS/D4 | BH2: KK/D4 | BI2: MM/D4 | BJ2: WodS/OBP | BK2: JvZ/D4 | BL2: Total | BM2: TG problem
A4: CAP3000 | B4: Capstone | C4: UCM | D4: J. Moes / E. Maegherman | F4: =E4/12 -> 0 | G4: =ROUNDUP(F4,0) -> 0 | H4: =IF(G4=0,0,E4/G4) -> 0 | J4: =I4*2*normuren!$B$26 -> 0 | K4: =IF(G4<3,normuren!$B$8,IF(AND(G4<6,G4>2),normuren!$B$9,IF(AND(G4<9,G4>5),normuren!$B$10,normuren!$B$11))) -> 15 | L4: =normuren!$B$28 -> 10 | M4: 20 | N4: =normuren!$B$29 -> 1.5 | AM4: X | AS4: X | BL4: =SUM(O4:BK4) -> 0 | BM4: =G4-BL4 -> 0 | BN4: =IF(BM4>0,"Problem","Oke") -> Oke | BO4: FP; zeta/ceren
A5: PRO1010 | B5: Introducing Academic Communication: A Writing Project | C5: UCM | D5: A. Wellum / A. Foster | F5: =E5/12 -> 0 | G5: =ROUNDUP(F5,0) -> 0 | H5: =IF(G5=0,0,E5/G5) -> 0 | J5: =I5*2*normuren!$B$26 -> 0 | K5: =IF(G5<3,normuren!$B$8,IF(AND(G5<6,G5>2),normuren!$B$9,IF(AND(G5<9,G5>5),normuren!$B$10,normuren!$B$11))) -> 15 | L5: =normuren!$B$28 -> 10 | M5: 20 | N5: =normuren!$B$29 -> 1.5 | V5: 1 | AU5: 3 | AW5: X | BD5: 3 | BL5: =SUM(O5:BK5) -> 7 | BM5: =G5-BL5 -> -7 | BN5: =IF(BM5>0,"Problem","Oke") -> Oke
A6: PRO1012 | B6: Research Project | C6: UCM | D6: J. Moes | F6: =E6/12 -> 0 | G6: =ROUNDUP(F6,0) -> 0 | H6: =IF(G6=0,0,E6/G6) -> 0 | J6: =I6*2*normuren!$B$26 -> 0 | K6: =IF(G6<3,normuren!$B$8,IF(AND(G6<6,G6>2),normuren!$B$9,IF(AND(G6<9,G6>5),normuren!$B$10,normuren!$B$11))) -> 15 | L6: =normuren!$B$28 -> 10 | M6: 20 | N6: =normuren!$B$29 -> 1.5 | O6: X | AE6: 1 | AG6: 1 | AW6: X | BG6: 1 | BJ6: 1 | BL6: =SUM(O6:BK6) -> 4 | BM6: =G6-BL6 -> -4 | BN6: =IF(BM6>0,"Problem","Oke") -> Oke
A7: PRO2003 | B7: Writing Project: "The Journal" | C7: UCM | D7: V. Lifriere | F7: =E7/12 -> 0 | G7: =ROUNDUP(F7,0) -> 0 | H7: =IF(G7=0,0,E7/G7) -> 0 | J7: =I7*2*normuren!$B$26 -> 0 | K7: =IF(G7<3,normuren!$B$8,IF(AND(G7<6,G7>2),normuren!$B$9,IF(AND(G7<9,G7>5),normuren!$B$10,normuren!$B$11))) -> 15 | L7: =normuren!$B$28 -> 10 | M7: 20 | N7: =normuren!$B$29 -> 1.5 | X7: X | AD7: 1 | AS7: NO | AW7: 1 | BB7: 1 | BC7: 1 | BI7: X | BL7: =SUM(O7:BK7) -> 4 | BM7: =G7-BL7 -> -4 | BN7: =IF(BM7>0,"Problem","Oke") -> Oke
A8: PRO2004 | B8: Project Academic Debate | C8: UCM | D8: C. Erkli | F8: =E8/12 -> 0 | G8: =ROUNDUP(F8,0) -> 0 | H8: =IF(G8=0,0,E8/G8) -> 0 | J8: =I8*2*normuren!$B$26 -> 0 | K8: =IF(G8<3,normuren!$B$8,IF(AND(G8<6,G8>2),normuren!$B$9,IF(AND(G8<9,G8>5),normuren!$B$10,normuren!$B$11))) -> 15 | L8: =normuren!$B$28 -> 10 | M8: 20 | N8: =normuren!$B$29 -> 1.5 | U8: 1 | X8: X | AO8: 1 | AR8: 1 | AW8: 1 | AZ8: ? | BB8: 1 | BG8: 1 | BI8: X | BL8: =SUM(O8:BK8) -> 6 | BM8: =G8-BL8 -> -6 | BN8: =IF(BM8>0,"Problem","Oke") -> Oke
A9: PRO2011 | B9: Project Deep Reading | C9: UCM | D9: K. Heidemann | F9: =E9/12 -> 0 | G9: =ROUNDUP(F9,0) -> 0 | H9: =IF(G9=0,0,E9/G9) -> 0 | J9: =I9*2*normuren!$B$26 -> 0 | K9: =IF(G9<3,normuren!$B$8,IF(AND(G9<6,G9>2),normuren!$B$9,IF(AND(G9<9,G9>5),normuren!$B$10,normuren!$B$11))) -> 15 | L9: =normuren!$B$28 -> 10 | M9: 20 | N9: =normuren!$B$29 -> 1.5 | Q9: 1 | S9: 1 | AP9: 1 | AR9: 1 | BC9: 1 | BL9: =SUM(O9:BK9) -> 5 | BM9: =G9-BL9 -> -5 | BN9: =IF(BM9>0,"Problem","Oke") -> Oke
A10: PRO2013 | B10: Project Design Thinking | C10: FASOS | D10: S. Schreibman | F10: =E10/12 -> 0 | G10: =ROUNDUP(F10,0) -> 0 | H10: =IF(G10=0,0,E10/G10) -> 0 | J10: =I10*2*normuren!$B$26 -> 0 | K10: =IF(G10<3,normuren!$B$8,IF(AND(G10<6,G10>2),normuren!$B$9,IF(AND(G10<9,G10>5),normuren!$B$10,normuren!$B$11))) -> 15 | L10: =normuren!$B$28 -> 10 | M10: 20 | N10: =normuren!$B$29 -> 1.5 | AA10: 1 | BL10: =SUM(O10:BK10) -> 1 | BM10: =G10-BL10 -> -1 | BN10: =IF(BM10>0,"Problem","Oke") -> Oke
A11: PRO3006 | B11: Conference | C11: UCM | D11: W. van Dellen | F11: =E11/12 -> 0 | G11: =ROUNDUP(F11,0) -> 0 | H11: =IF(G11=0,0,E11/G11) -> 0 | J11: =I11*2*normuren!$B$26 -> 0 | K11: =IF(G11<3,normuren!$B$8,IF(AND(G11<6,G11>2),normuren!$B$9,IF(AND(G11<9,G11>5),normuren!$B$10,normuren!$B$11))) -> 15 | L11: =normuren!$B$28 -> 10 | M11: 20 | N11: =normuren!$B$29 -> 1.5 | T11: 1 | BL11: =SUM(O11:BK11) -> 1 | BM11: =G11-BL11 -> -1 | BN11: =IF(BM11>0,"Problem","Oke") -> Oke
A12: PRO3008 | B12: Think Tank | C12: UCM | D12: W. van Dellen | F12: =E12/12 -> 0 | G12: =ROUNDUP(F12,0) -> 0 | H12: =IF(G12=0,0,E12/G12) -> 0 | J12: =I12*2*normuren!$B$26 -> 0 | K12: =IF(G12<3,normuren!$B$8,IF(AND(G12<6,G12>2),normuren!$B$9,IF(AND(G12<9,G12>5),normuren!$B$10,normuren!$B$11))) -> 15 | L12: =normuren!$B$28 -> 10 | M12: 20 | N12: =normuren!$B$29 -> 1.5 | O12: X | P12: X | S12: NO | T12: 1 | U12: 1 | AL12: 1 | BI12: X | BL12: =SUM(O12:BK12) -> 3 | BM12: =G12-BL12 -> -3 | BN12: =IF(BM12>0,"Problem","Oke") -> Oke
A13: PRO3009 | B13: Ethnography and Qualitative Interviewing III | C13: UCM | D13: U. Müller | F13: =E13/12 -> 0 | G13: =ROUNDUP(F13,0) -> 0 | H13: =IF(G13=0,0,E13/G13) -> 0 | J13: =I13*2*normuren!$B$26 -> 0 | K13: =IF(G13<3,normuren!$B$8,IF(AND(G13<6,G13>2),normuren!$B$9,IF(AND(G13<9,G13>5),normuren!$B$10,normuren!$B$11))) -> 15 | L13: =normuren!$B$28 -> 10 | M13: 20 | N13: =normuren!$B$29 -> 1.5 | AH13: 2 | BJ13: 1 | BL13: =SUM(O13:BK13) -> 3 | BM13: =G13-BL13 -> -3 | BN13: =IF(BM13>0,"Problem","Oke") -> Oke
A14: PRO3014 | B14: Science Research Project: Biomedical Engineering | C14: FHML | D14: A. van Apeldoorn | F14: =E14/12 -> 0 | G14: =ROUNDUP(F14,0) -> 0 | H14: =IF(G14=0,0,E14/G14) -> 0 | J14: =I14*2*normuren!$B$26 -> 0 | K14: =IF(G14<3,normuren!$B$8,IF(AND(G14<6,G14>2),normuren!$B$9,IF(AND(G14<9,G14>5),normuren!$B$10,normuren!$B$11))) -> 15 | L14: =normuren!$B$28 -> 10 | M14: 20 | N14: =normuren!$B$29 -> 1.5 | BL14: =SUM(O14:BK14) -> 0 | BM14: =G14-BL14 -> 0 | BN14: =IF(BM14>0,"Problem","Oke") -> Oke
A15: PRO3015 | B15: Research Studio, where art and academia meet | C15: UCM | D15: I. Römgens | F15: =E15/12 -> 0 | G15: =ROUNDUP(F15,0) -> 0 | H15: =IF(G15=0,0,E15/G15) -> 0 | J15: =I15*2*normuren!$B$26 -> 0 | K15: =IF(G15<3,normuren!$B$8,IF(AND(G15<6,G15>2),normuren!$B$9,IF(AND(G15<9,G15>5),normuren!$B$10,normuren!$B$11))) -> 15 | L15: =normuren!$B$28 -> 10 | M15: 20 | N15: =normuren!$B$29 -> 1.5 | AL15: 1 | BL15: =SUM(O15:BK15) -> 1 | BM15: =G15-BL15 -> -1 | BN15: =IF(BM15>0,"Problem","Oke") -> Oke
A16: PRO3018 | B16: Internationally Taught Project (registration via Form in MYUCM) | C16: UCM | D16: M. Stout | F16: =E16/12 -> 0 | G16: =ROUNDUP(F16,0) -> 0 | H16: =IF(G16=0,0,E16/G16) -> 0 | J16: =I16*2*normuren!$B$26 -> 0 | K16: =IF(G16<3,normuren!$B$8,IF(AND(G16<6,G16>2),normuren!$B$9,IF(AND(G16<9,G16>5),normuren!$B$10,normuren!$B$11))) -> 15 | L16: =normuren!$B$28 -> 10 | M16: 20 | N16: =normuren!$B$29 -> 1.5 | BL16: =SUM(O16:BK16) -> 0 | BM16: =G16-BL16 -> 0 | BN16: =IF(BM16>0,"Problem","Oke") -> Oke
A17: PRO3019 | B17: Applied Ethics: Ethical decision-making in public life, research programs, and professional practices | C17: UCM | D17: J. Welie | F17: =E17/12 -> 0 | G17: =ROUNDUP(F17,0) -> 0 | H17: =IF(G17=0,0,E17/G17) -> 0 | J17: =I17*2*normuren!$B$26 -> 0 | K17: =IF(G17<3,normuren!$B$8,IF(AND(G17<6,G17>2),normuren!$B$9,IF(AND(G17<9,G17>5),normuren!$B$10,normuren!$B$11))) -> 15 | L17: =normuren!$B$28 -> 10 | M17: 20 | N17: =normuren!$B$29 -> 1.5 | O17: X | AR17: 2 | BB17: X | BL17: =SUM(O17:BK17) -> 2 | BM17: =G17-BL17 -> -2 | BN17: =IF(BM17>0,"Problem","Oke") -> Oke
A18: UGR3001 | B18: MaRBLe Undergraduate Research | C18: UCM | D18: J. Moes / U. Müller | F18: =E18/12 -> 0 | G18: =ROUNDUP(F18,0) -> 0 | H18: =IF(G18=0,0,E18/G18) -> 0 | AM18: X | BL18: =SUM(O18:BK18) -> 0 | BM18: =G18-BL18 -> 0 | BN18: =IF(BM18>0,"Problem","Oke") -> Oke
A19: UGR3003 | B19: Applied Research & Internship Project | C19: UCM | D19: I. Römgens | F19: =E19/12 -> 0 | G19: =ROUNDUP(F19,0) -> 0 | H19: =IF(G19=0,0,E19/G19) -> 0 | AG19: X | AK19: X | BL19: =SUM(O19:BK19) -> 0 | BM19: =G19-BL19 -> 0 | BN19: =IF(BM19>0,"Problem","Oke") -> Oke
A21: Tutorgroups | G21: =SUM(G4:G20) -> 0 | O21: =SUM(O3:O18) -> 0 | P21: =SUM(P3:P18) -> 0 | Q21: =SUM(Q3:Q18) -> 1 | R21: =SUM(R3:R18) -> 0 | S21: =SUM(S3:S18) -> 1 | T21: =SUM(T3:T18) -> 2 | U21: =SUM(U3:U18) -> 2 | V21: =SUM(V3:V18) -> 1 | ... AU21: =SUM(AU3:AU18) -> 3 | AX21: =SUM(AX3:AX18) -> 0 | BA21: =SUM(BA3:BA18) -> 0 | BB21: =SUM(BB3:BB18) -> 2 | BG21: =SUM(BG3:BG18) -> 2 | BH21: =SUM(BH3:BH18) -> 0 | BK21: =SUM(BK3:BK18) -> 0 | BL21: =SUM(BL3:BL18) -> 37 | BM21: =SUM(BM3:BM18) -> -37
A22: Tutorhours | O22: =SUM(O4:O20) -> 0 | P22: =SUM(P4:P20) -> 0 | Q22: =SUM(Q4:Q20) -> 1 | R22: =SUM(R4:R20) -> 0 | S22: =SUM(S4:S20) -> 1 | T22: =SUM(T4:T20) -> 2 | U22: =SUM(U4:U20) -> 2 | V22: =SUM(V4:V20) -> 1 | ... AU22: =SUM(AU4:AU20) -> 3 | AX22: =SUM(AX4:AX20) -> 0 | BA22: =SUM(BA4:BA20) -> 0 | BB22: =SUM(BB4:BB20) -> 2 | BG22: =SUM(BG4:BG20) -> 2 | BH22: =SUM(BH4:BH20) -> 0 | BK22: =SUM(BK4:BK20) -> 0 | BL22: =SUMPRODUCT($L$3:$L$47,BL3:BL18) -> #VALUE!
A23: Correction | O23: =SUM(O5:O21) -> 0 | P23: =SUM(P5:P21) -> 0 | Q23: =SUM(Q5:Q21) -> 2 | R23: =SUM(R5:R21) -> 0 | S23: =SUM(S5:S21) -> 2 | T23: =SUM(T5:T21) -> 4 | U23: =SUM(U5:U21) -> 4 | V23: =SUM(V5:V21) -> 2 | ... AU23: =SUM(AU5:AU21) -> 6 | AX23: =SUM(AX5:AX21) -> 0 | BA23: =SUM(BA5:BA21) -> 0 | BB23: =SUM(BB5:BB21) -> 4 | BG23: =SUM(BG5:BG21) -> 4 | BH23: =SUM(BH5:BH21) -> 0 | BK23: =SUM(BK5:BK21) -> 0 | BL23: =SUMPRODUCT($H$3:$H$47,$N$3:$N$47,BL3:BL18) -> #VALUE!
A24: Coordination | O24: =SUM(O6:O22) -> 0 | P24: =SUM(P6:P22) -> 0 | Q24: =SUM(Q6:Q22) -> 3 | R24: =SUM(R6:R22) -> 0 | S24: =SUM(S6:S22) -> 3 | T24: =SUM(T6:T22) -> 6 | U24: =SUM(U6:U22) -> 6 | V24: =SUM(V6:V22) -> 2 | ... AU24: =SUM(AU6:AU22) -> 6 | AX24: =SUM(AX6:AX22) -> 0 | BA24: =SUM(BA6:BA22) -> 0 | BB24: =SUM(BB6:BB22) -> 6 | BG24: =SUM(BG6:BG22) -> 6 | BH24: =SUM(BH6:BH22) -> 0 | BK24: =SUM(BK6:BK22) -> 0 | BL24: =DSUM($D$2:$BL$47,$K$2,BL30:BL31) -> 0
A25: Total Teaching Hours per Period | O25: =SUM(O7:O23) -> 0 | P25: =SUM(P7:P23) -> 0 | Q25: =SUM(Q7:Q23) -> 5 | R25: =SUM(R7:R23) -> 0 | S25: =SUM(S7:S23) -> 5 | T25: =SUM(T7:T23) -> 10 | U25: =SUM(U7:U23) -> 10 | V25: =SUM(V7:V23) -> 4 | ... AU25: =SUM(AU7:AU23) -> 12 | AX25: =SUM(AX7:AX23) -> 0 | BA25: =SUM(BA7:BA23) -> 0 | BB25: =SUM(BB7:BB23) -> 10 | BG25: =SUM(BG7:BG23) -> 9 | BH25: =SUM(BH7:BH23) -> 0 | BK25: =SUM(BK7:BK23) -> 0 | BL25: =SUM(BL22:BL24) -> #VALUE!
A26: Total Teaching Hours per Week | O26: =SUM(O8:O24) -> 0 | P26: =SUM(P8:P24) -> 0 | Q26: =SUM(Q8:Q24) -> 8 | R26: =SUM(R8:R24) -> 0 | S26: =SUM(S8:S24) -> 8 | T26: =SUM(T8:T24) -> 16 | U26: =SUM(U8:U24) -> 16 | V26: =SUM(V8:V24) -> 6 | ... AU26: =SUM(AU8:AU24) -> 18 | AX26: =SUM(AX8:AX24) -> 0 | BA26: =SUM(BA8:BA24) -> 0 | BB26: =SUM(BB8:BB24) -> 15 | BG26: =SUM(BG8:BG24) -> 15 | BH26: =SUM(BH8:BH24) -> 0 | BK26: =SUM(BK8:BK24) -> 0
A27: Fixed Role Hours per Week | O27: =SUM(O9:O25) -> 0 | P27: =SUM(P9:P25) -> 0 | Q27: =SUM(Q9:Q25) -> 13 | R27: =SUM(R9:R25) -> 0 | S27: =SUM(S9:S25) -> 13 | T27: =SUM(T9:T25) -> 26 | U27: =SUM(U9:U25) -> 25 | V27: =SUM(V9:V25) -> 10 | ... AU27: =SUM(AU9:AU25) -> 30 | AX27: =SUM(AX9:AX25) -> 0 | BA27: =SUM(BA9:BA25) -> 0 | BB27: =SUM(BB9:BB25) -> 24 | BG27: =SUM(BG9:BG25) -> 23 | BH27: =SUM(BH9:BH25) -> 0 | BK27: =SUM(BK9:BK25) -> 0
A28: Contract Hours per Week | O28: =SUM(O10:O26) -> 0 | P28: =SUM(P10:P26) -> 0 | Q28: =SUM(Q10:Q26) -> 20 | R28: =SUM(R10:R26) -> 0 | S28: =SUM(S10:S26) -> 20 | T28: =SUM(T10:T26) -> 42 | U28: =SUM(U10:U26) -> 41 | V28: =SUM(V10:V26) -> 16 | ... AU28: =SUM(AU10:AU26) -> 48 | AX28: =SUM(AX10:AX26) -> 0 | BA28: =SUM(BA10:BA26) -> 0 | BB28: =SUM(BB10:BB26) -> 39 | BG28: =SUM(BG10:BG26) -> 38 | BH28: =SUM(BH10:BH26) -> 0 | BK28: =SUM(BK10:BK26) -> 0
A29: Hours Remaining per Week | O29: =SUM(O11:O27) -> 0 | P29: =SUM(P11:P27) -> 0 | Q29: =SUM(Q11:Q27) -> 33 | R29: =SUM(R11:R27) -> 0 | S29: =SUM(S11:S27) -> 33 | T29: =SUM(T11:T27) -> 68 | U29: =SUM(U11:U27) -> 66 | V29: =SUM(V11:V27) -> 26 | ... AU29: =SUM(AU11:AU27) -> 78 | AX29: =SUM(AX11:AX27) -> 0 | BA29: =SUM(BA11:BA27) -> 0 | BB29: =SUM(BB11:BB27) -> 63 | BG29: =SUM(BG11:BG27) -> 61 | BH29: =SUM(BH11:BH27) -> 0 | BK29: =SUM(BK11:BK27) -> 0
O30: CO | P30: =P2 -> Lbe | Q30: =Q2 -> LB | R30: =R2 -> Sca | S30: =S2 -> TD | T30: =T2 -> WvD | U30: =U2 -> CE | V30: =V2 -> AF | W30: =W2 -> WG | ... AT30: =AT2 -> CYPL | AU30: CO | AX30: CO | BA30: CO | BB30: CO | BG30: CO | BH30: CO | BK30: CO | BL30: CO
O31: =O2 -> FAC | P31: =P2 -> Lbe | Q31: =Q2 -> LB | R31: =R2 -> Sca | S31: =S2 -> TD | T31: =T2 -> WvD | U31: =U2 -> CE | V31: =V2 -> AF | ... AU31: =AU2 -> JB/OBP | AX31: =AX2 -> XT/D4 | BA31: =BA2 -> CG/D4 | BB31: =#REF! -> #REF! | BG31: =BG2 -> WS/D4 | BH31: =BH2 -> KK/D4 | BK31: =BK2 -> JvZ/D4 | BL31: =BL2 -> Total
A35: UCM
A36: No Teaching
A37: Teaching preference

Sheet PERIOD 4
A1: PERIOD 4 | K1: Hours | AU1: Junior Lecturers (D4) & OBP
A2: CODE | B2: COURSE TITLE | C2: Faculty | D2: COORDINATOR | E2: NR | F2: TG | G2: TG | H2: ST/TG | I2: Lect | J2: lect | K2: Coor | L2: per TG regular staff | M2: Per TG 1st Year JTF | N2: Per ST | O2: FAC | P2: Lbe | Q2: LB | R2: Sca | S2: TD | T2: WvD | U2: CE | V2: AF | W2: WG | X2: TG | Y2: RH | Z2: CH | AA2: KH | AB2: MH | AC2: MK | AD2: VL | AE2: EM | AF2: DM | AG2: JM | AH2: UM | AI2: AO | AJ2: JvP | AK2: CR | AL2: IR | AM2: JS | AN2: BS | AO2: MS | AP2: PV | AQ2: DV | AR2: JW | AS2: AW | AT2: CYPL | AU2: JB/OBP | AV2: SB/D4 | AW2: CC/OBP | AX2: XT/D4 | AY2: RvE/D4 | AZ2: ZE/ OBP | BA2: CG/D4 | BB2: JH/D4 | BC2: WH/D4 | BD2: JvL/D4 | BE2: IM/D4 | BF2: APT/D4 | BG2: WS/D4 | BH2: KK/D4 | BI2: MM/D4 | BJ2: JvZ/D4 | BK2: Total | BL2: Problem
A4: CAP3000 | B4: Capstone | C4: UCM | D4: J. Moes / E. Maegherman | F4: =E4/12 -> 0 | G4: =ROUNDUP(F4,0) -> 0 | H4: =IF(G4=0,0,E4/G4) -> 0 | R4: 1 | V4: 1 | X4: x | Y4: ? | AA4: 1 | AE4: X | AG4: X | AK4: 1 | AP4: X | AR4: X | AS4: X | AT4: 1
A5: COR1003 | B5: Contemporary World History | C5: UCM | D5: M. Stout | F5: =E5/12 -> 0 | G5: =ROUNDUP(F5,0) -> 0 | H5: =IF(G5=0,0,E5/G5) -> 0 | J5: =I5*2*normuren!$B$26 -> 0 | K5: =IF(G5<3,normuren!$B$8,IF(AND(G5<6,G5>2),normuren!$B$9,IF(AND(G5<9,G5>5),normuren!$B$10,normuren!$B$11))) -> 15 | L5: =normuren!$B$24*2*12 -> 36 | M5: =normuren!$B$25*2*12 -> 45.6 | N5: =normuren!$B$29 -> 1.5 | V5: NO | AO5: 2 | AZ5: X | BI5: NO | BK5: =SUM(O5:BJ5) -> 2 | BL5: =G5-BK5 -> -2 | BM5: =IF(BL5>0,"Problem","Oke") -> Oke | BN5: FP; zeta/ceren
A6: COR1006 | B6: Science, Reason and Human Progress | C6: UCM | D6: M. Heins | F6: =E6/12 -> 0 | G6: =ROUNDUP(F6,0) -> 0 | H6: =IF(G6=0,0,E6/G6) -> 0 | J6: =I6*2*normuren!$B$26 -> 0 | K6: =IF(G6<3,normuren!$B$8,IF(AND(G6<6,G6>2),normuren!$B$9,IF(AND(G6<9,G6>5),normuren!$B$10,normuren!$B$11))) -> 15 | L6: =normuren!$B$24*2*12 -> 36 | M6: =normuren!$B$25*2*12 -> 45.6 | N6: =normuren!$B$29 -> 1.5 | O6: X | X6: X | AU6: 3 | AX6: 3 | BA6: X | BB6: 3 | BD6: NO | BI6: X | BK6: =SUM(O6:BJ6) -> 9 | BL6: =G6-BK6 -> -9 | BM6: =IF(BL6>0,"Problem","Oke") -> Oke
